{"nbformat":4,"nbformat_minor":0,"metadata":{"colab":{"provenance":[],"mount_file_id":"18hXeCe1XNPbOH9ytFYEHX5z619s8Bf7t","authorship_tag":"ABX9TyNDTX1MB2AfyAj3RqMNC779"},"kernelspec":{"name":"python3","display_name":"Python 3"},"language_info":{"name":"python"}},"cells":[{"cell_type":"code","source":["ls"],"metadata":{"colab":{"base_uri":"https://localhost:8080/"},"id":"85sHX8dLr97h","executionInfo":{"status":"ok","timestamp":1713804253535,"user_tz":240,"elapsed":13,"user":{"displayName":"Anpu Auroville","userId":"11856823287554841366"}},"outputId":"783463a9-f970-48ed-cac3-de0602b3e0fa"},"execution_count":null,"outputs":[{"output_type":"stream","name":"stdout","text":["\u001b[0m\u001b[01;34mdrive\u001b[0m/  \u001b[01;34msample_data\u001b[0m/\n"]}]},{"cell_type":"code","source":["cd drive/MyDrive/MultiOn/"],"metadata":{"colab":{"base_uri":"https://localhost:8080/"},"id":"-mvuXisUsYaL","executionInfo":{"status":"ok","timestamp":1713905423673,"user_tz":240,"elapsed":168,"user":{"displayName":"Anpu Auroville","userId":"11856823287554841366"}},"outputId":"be5d210d-5911-4ab7-dbf9-967ef71ef3f0"},"execution_count":null,"outputs":[{"output_type":"stream","name":"stdout","text":["/content/drive/MyDrive/MultiOn\n"]}]},{"cell_type":"code","source":["!touch /content/drive/MyDrive/MultiOn/ngrok.yml"],"metadata":{"id":"xdOCxKvpzCw8"},"execution_count":null,"outputs":[]},{"cell_type":"code","source":["!echo \"authtoken:2fWDHDrSDxZAyrdTdF1GDWMz7fd_6t6TtPrvyJTQVuQ7c1zrZ\" > /content/ngrok.yml"],"metadata":{"id":"BlF5aTL9zIxY"},"execution_count":null,"outputs":[]},{"cell_type":"code","source":["import getpass\n","from pyngrok import conf\n","conf.get_default().auth_token = getpass.getpass()"],"metadata":{"colab":{"base_uri":"https://localhost:8080/"},"id":"QdGiH-lz3ERQ","executionInfo":{"status":"ok","timestamp":1713907932007,"user_tz":240,"elapsed":2979,"user":{"displayName":"Anpu Auroville","userId":"11856823287554841366"}},"outputId":"fa2a7824-0fa6-47cd-fbf4-2cffd3389a5f"},"execution_count":null,"outputs":[{"name":"stdout","output_type":"stream","text":["··········\n"]}]},{"cell_type":"code","source":["#@title Installations\n","%%capture\n","!pip install openai\n","!pip install langchain\n","!pip install multion\n","!pip3 install salesforce-lavis"],"metadata":{"id":"bouC7XSnssIQ"},"execution_count":null,"outputs":[]},{"cell_type":"code","source":["!pip install fastapi\n","!pip install nest-asyncio"],"metadata":{"id":"Vqkklk0rx9w4"},"execution_count":null,"outputs":[]},{"cell_type":"code","source":["%%capture\n","!pip install uvicorn[standard]\n","!pip install python-multipart"],"metadata":{"id":"OO7SvgF0tEA4"},"execution_count":null,"outputs":[]},{"cell_type":"code","source":["import requests"],"metadata":{"id":"UYHoRd3uwCwj"},"execution_count":null,"outputs":[]},{"cell_type":"code","source":["!pip install ngrok"],"metadata":{"id":"iZHn7SvtBlj8","colab":{"base_uri":"https://localhost:8080/"},"executionInfo":{"status":"ok","timestamp":1713907755217,"user_tz":240,"elapsed":8866,"user":{"displayName":"Anpu Auroville","userId":"11856823287554841366"}},"outputId":"838f11c1-a1f1-4c3a-a880-536b3ac850cf"},"execution_count":null,"outputs":[{"output_type":"stream","name":"stdout","text":["Collecting ngrok\n","  Downloading ngrok-1.2.0-cp37-abi3-manylinux_2_17_x86_64.manylinux2014_x86_64.whl (2.9 MB)\n","\u001b[2K     \u001b[90m━━━━━━━━━━━━━━━━━━━━━━━━━━━━━━━━━━━━━━━━\u001b[0m \u001b[32m2.9/2.9 MB\u001b[0m \u001b[31m21.5 MB/s\u001b[0m eta \u001b[36m0:00:00\u001b[0m\n","\u001b[?25hInstalling collected packages: ngrok\n","Successfully installed ngrok-1.2.0\n"]}]},{"cell_type":"code","source":["!pip install pyngrok"],"metadata":{"colab":{"base_uri":"https://localhost:8080/"},"id":"NKMHhfxcOKpe","executionInfo":{"status":"ok","timestamp":1713905899392,"user_tz":240,"elapsed":8987,"user":{"displayName":"Anpu Auroville","userId":"11856823287554841366"}},"outputId":"1d23c2a3-15e4-4b05-ea5b-5baf5459c8a2"},"execution_count":null,"outputs":[{"output_type":"stream","name":"stdout","text":["Collecting pyngrok\n","  Downloading pyngrok-7.1.6-py3-none-any.whl (22 kB)\n","Requirement already satisfied: PyYAML>=5.1 in /usr/local/lib/python3.10/dist-packages (from pyngrok) (6.0.1)\n","Installing collected packages: pyngrok\n","Successfully installed pyngrok-7.1.6\n"]}]},{"cell_type":"code","source":["!python main.py"],"metadata":{"colab":{"base_uri":"https://localhost:8080/"},"id":"mZrZPh4I3vhy","executionInfo":{"status":"ok","timestamp":1713924696009,"user_tz":240,"elapsed":1966917,"user":{"displayName":"Anpu Auroville","userId":"11856823287554841366"}},"outputId":"1ecf80f2-5dcc-48a0-b1c9-8d319d99f0e1"},"execution_count":35,"outputs":[{"output_type":"stream","name":"stdout","text":["2024-04-24 01:38:56.020313: E external/local_xla/xla/stream_executor/cuda/cuda_dnn.cc:9261] Unable to register cuDNN factory: Attempting to register factory for plugin cuDNN when one has already been registered\n","2024-04-24 01:38:56.020442: E external/local_xla/xla/stream_executor/cuda/cuda_fft.cc:607] Unable to register cuFFT factory: Attempting to register factory for plugin cuFFT when one has already been registered\n","2024-04-24 01:38:56.033487: E external/local_xla/xla/stream_executor/cuda/cuda_blas.cc:1515] Unable to register cuBLAS factory: Attempting to register factory for plugin cuBLAS when one has already been registered\n","2024-04-24 01:38:59.108449: W tensorflow/compiler/tf2tensorrt/utils/py_utils.cc:38] TF-TRT Warning: Could not find TensorRT\n","Public URL: https://d578-34-106-156-105.ngrok-free.app\n","\u001b[32mINFO\u001b[0m:     Started server process [\u001b[36m70533\u001b[0m]\n","\u001b[32mINFO\u001b[0m:     Waiting for application startup.\n","\u001b[32mINFO\u001b[0m:     Application startup complete.\n","\u001b[32mINFO\u001b[0m:     Uvicorn running on \u001b[1mhttp://127.0.0.1:8000\u001b[0m (Press CTRL+C to quit)\n","\u001b[32mINFO\u001b[0m:     2603:6080:65f0:c9d0:8175:84f2:1d17:b30e:0 - \"\u001b[1mGET / HTTP/1.1\u001b[0m\" \u001b[31m404 Not Found\u001b[0m\n","\u001b[32mINFO\u001b[0m:     2603:6080:65f0:c9d0:8175:84f2:1d17:b30e:0 - \"\u001b[1mGET /favicon.ico HTTP/1.1\u001b[0m\" \u001b[31m404 Not Found\u001b[0m\n","\u001b[32mINFO\u001b[0m:     35.231.57.121:0 - \"\u001b[1mPOST /get_visual_prompt HTTP/1.1\u001b[0m\" \u001b[91m500 Internal Server Error\u001b[0m\n","\u001b[31mERROR\u001b[0m:    Exception in ASGI application\n","Traceback (most recent call last):\n","  File \"/usr/local/lib/python3.10/dist-packages/httpx/_transports/default.py\", line 69, in map_httpcore_exceptions\n","    yield\n","  File \"/usr/local/lib/python3.10/dist-packages/httpx/_transports/default.py\", line 233, in handle_request\n","    resp = self._pool.handle_request(req)\n","  File \"/usr/local/lib/python3.10/dist-packages/httpcore/_sync/connection_pool.py\", line 216, in handle_request\n","    raise exc from None\n","  File \"/usr/local/lib/python3.10/dist-packages/httpcore/_sync/connection_pool.py\", line 196, in handle_request\n","    response = connection.handle_request(\n","  File \"/usr/local/lib/python3.10/dist-packages/httpcore/_sync/connection.py\", line 101, in handle_request\n","    return self._connection.handle_request(request)\n","  File \"/usr/local/lib/python3.10/dist-packages/httpcore/_sync/http11.py\", line 143, in handle_request\n","    raise exc\n","  File \"/usr/local/lib/python3.10/dist-packages/httpcore/_sync/http11.py\", line 113, in handle_request\n","    ) = self._receive_response_headers(**kwargs)\n","  File \"/usr/local/lib/python3.10/dist-packages/httpcore/_sync/http11.py\", line 186, in _receive_response_headers\n","    event = self._receive_event(timeout=timeout)\n","  File \"/usr/local/lib/python3.10/dist-packages/httpcore/_sync/http11.py\", line 224, in _receive_event\n","    data = self._network_stream.read(\n","  File \"/usr/local/lib/python3.10/dist-packages/httpcore/_backends/sync.py\", line 124, in read\n","    with map_exceptions(exc_map):\n","  File \"/usr/lib/python3.10/contextlib.py\", line 153, in __exit__\n","    self.gen.throw(typ, value, traceback)\n","  File \"/usr/local/lib/python3.10/dist-packages/httpcore/_exceptions.py\", line 14, in map_exceptions\n","    raise to_exc(exc) from exc\n","httpcore.ReadTimeout: The read operation timed out\n","\n","The above exception was the direct cause of the following exception:\n","\n","Traceback (most recent call last):\n","  File \"/usr/local/lib/python3.10/dist-packages/uvicorn/protocols/http/httptools_impl.py\", line 411, in run_asgi\n","    result = await app(  # type: ignore[func-returns-value]\n","  File \"/usr/local/lib/python3.10/dist-packages/uvicorn/middleware/proxy_headers.py\", line 69, in __call__\n","    return await self.app(scope, receive, send)\n","  File \"/usr/local/lib/python3.10/dist-packages/fastapi/applications.py\", line 1054, in __call__\n","    await super().__call__(scope, receive, send)\n","  File \"/usr/local/lib/python3.10/dist-packages/starlette/applications.py\", line 123, in __call__\n","    await self.middleware_stack(scope, receive, send)\n","  File \"/usr/local/lib/python3.10/dist-packages/starlette/middleware/errors.py\", line 186, in __call__\n","    raise exc\n","  File \"/usr/local/lib/python3.10/dist-packages/starlette/middleware/errors.py\", line 164, in __call__\n","    await self.app(scope, receive, _send)\n","  File \"/usr/local/lib/python3.10/dist-packages/starlette/middleware/cors.py\", line 85, in __call__\n","    await self.app(scope, receive, send)\n","  File \"/usr/local/lib/python3.10/dist-packages/starlette/middleware/exceptions.py\", line 65, in __call__\n","    await wrap_app_handling_exceptions(self.app, conn)(scope, receive, send)\n","  File \"/usr/local/lib/python3.10/dist-packages/starlette/_exception_handler.py\", line 64, in wrapped_app\n","    raise exc\n","  File \"/usr/local/lib/python3.10/dist-packages/starlette/_exception_handler.py\", line 53, in wrapped_app\n","    await app(scope, receive, sender)\n","  File \"/usr/local/lib/python3.10/dist-packages/starlette/routing.py\", line 756, in __call__\n","    await self.middleware_stack(scope, receive, send)\n","  File \"/usr/local/lib/python3.10/dist-packages/starlette/routing.py\", line 776, in app\n","    await route.handle(scope, receive, send)\n","  File \"/usr/local/lib/python3.10/dist-packages/starlette/routing.py\", line 297, in handle\n","    await self.app(scope, receive, send)\n","  File \"/usr/local/lib/python3.10/dist-packages/starlette/routing.py\", line 77, in app\n","    await wrap_app_handling_exceptions(app, request)(scope, receive, send)\n","  File \"/usr/local/lib/python3.10/dist-packages/starlette/_exception_handler.py\", line 64, in wrapped_app\n","    raise exc\n","  File \"/usr/local/lib/python3.10/dist-packages/starlette/_exception_handler.py\", line 53, in wrapped_app\n","    await app(scope, receive, sender)\n","  File \"/usr/local/lib/python3.10/dist-packages/starlette/routing.py\", line 72, in app\n","    response = await func(request)\n","  File \"/usr/local/lib/python3.10/dist-packages/fastapi/routing.py\", line 278, in app\n","    raw_response = await run_endpoint_function(\n","  File \"/usr/local/lib/python3.10/dist-packages/fastapi/routing.py\", line 191, in run_endpoint_function\n","    return await dependant.call(**values)\n","  File \"/content/drive/MyDrive/MultiOn/main.py\", line 115, in get_visual_prompt\n","    browse = multion.browse(cmd=input_command[0],local=True)\n","  File \"/usr/local/lib/python3.10/dist-packages/multion/client.py\", line 135, in browse\n","    _response = self._client_wrapper.httpx_client.request(\n","  File \"/usr/local/lib/python3.10/dist-packages/multion/core/http_client.py\", line 94, in request\n","    response = self.httpx_client.request(*args, **kwargs)\n","  File \"/usr/local/lib/python3.10/dist-packages/httpx/_client.py\", line 827, in request\n","    return self.send(request, auth=auth, follow_redirects=follow_redirects)\n","  File \"/usr/local/lib/python3.10/dist-packages/httpx/_client.py\", line 914, in send\n","    response = self._send_handling_auth(\n","  File \"/usr/local/lib/python3.10/dist-packages/httpx/_client.py\", line 942, in _send_handling_auth\n","    response = self._send_handling_redirects(\n","  File \"/usr/local/lib/python3.10/dist-packages/httpx/_client.py\", line 979, in _send_handling_redirects\n","    response = self._send_single_request(request)\n","  File \"/usr/local/lib/python3.10/dist-packages/httpx/_client.py\", line 1015, in _send_single_request\n","    response = transport.handle_request(request)\n","  File \"/usr/local/lib/python3.10/dist-packages/httpx/_transports/default.py\", line 232, in handle_request\n","    with map_httpcore_exceptions():\n","  File \"/usr/lib/python3.10/contextlib.py\", line 153, in __exit__\n","    self.gen.throw(typ, value, traceback)\n","  File \"/usr/local/lib/python3.10/dist-packages/httpx/_transports/default.py\", line 86, in map_httpcore_exceptions\n","    raise mapped_exc(message) from exc\n","httpx.ReadTimeout: The read operation timed out\n","\u001b[32mINFO\u001b[0m:     35.231.57.121:0 - \"\u001b[1mPOST /get_visual_prompt HTTP/1.1\u001b[0m\" \u001b[91m500 Internal Server Error\u001b[0m\n","\u001b[31mERROR\u001b[0m:    Exception in ASGI application\n","Traceback (most recent call last):\n","  File \"/usr/local/lib/python3.10/dist-packages/httpx/_transports/default.py\", line 69, in map_httpcore_exceptions\n","    yield\n","  File \"/usr/local/lib/python3.10/dist-packages/httpx/_transports/default.py\", line 233, in handle_request\n","    resp = self._pool.handle_request(req)\n","  File \"/usr/local/lib/python3.10/dist-packages/httpcore/_sync/connection_pool.py\", line 216, in handle_request\n","    raise exc from None\n","  File \"/usr/local/lib/python3.10/dist-packages/httpcore/_sync/connection_pool.py\", line 196, in handle_request\n","    response = connection.handle_request(\n","  File \"/usr/local/lib/python3.10/dist-packages/httpcore/_sync/connection.py\", line 101, in handle_request\n","    return self._connection.handle_request(request)\n","  File \"/usr/local/lib/python3.10/dist-packages/httpcore/_sync/http11.py\", line 143, in handle_request\n","    raise exc\n","  File \"/usr/local/lib/python3.10/dist-packages/httpcore/_sync/http11.py\", line 113, in handle_request\n","    ) = self._receive_response_headers(**kwargs)\n","  File \"/usr/local/lib/python3.10/dist-packages/httpcore/_sync/http11.py\", line 186, in _receive_response_headers\n","    event = self._receive_event(timeout=timeout)\n","  File \"/usr/local/lib/python3.10/dist-packages/httpcore/_sync/http11.py\", line 224, in _receive_event\n","    data = self._network_stream.read(\n","  File \"/usr/local/lib/python3.10/dist-packages/httpcore/_backends/sync.py\", line 124, in read\n","    with map_exceptions(exc_map):\n","  File \"/usr/lib/python3.10/contextlib.py\", line 153, in __exit__\n","    self.gen.throw(typ, value, traceback)\n","  File \"/usr/local/lib/python3.10/dist-packages/httpcore/_exceptions.py\", line 14, in map_exceptions\n","    raise to_exc(exc) from exc\n","httpcore.ReadTimeout: The read operation timed out\n","\n","The above exception was the direct cause of the following exception:\n","\n","Traceback (most recent call last):\n","  File \"/usr/local/lib/python3.10/dist-packages/uvicorn/protocols/http/httptools_impl.py\", line 411, in run_asgi\n","    result = await app(  # type: ignore[func-returns-value]\n","  File \"/usr/local/lib/python3.10/dist-packages/uvicorn/middleware/proxy_headers.py\", line 69, in __call__\n","    return await self.app(scope, receive, send)\n","  File \"/usr/local/lib/python3.10/dist-packages/fastapi/applications.py\", line 1054, in __call__\n","    await super().__call__(scope, receive, send)\n","  File \"/usr/local/lib/python3.10/dist-packages/starlette/applications.py\", line 123, in __call__\n","    await self.middleware_stack(scope, receive, send)\n","  File \"/usr/local/lib/python3.10/dist-packages/starlette/middleware/errors.py\", line 186, in __call__\n","    raise exc\n","  File \"/usr/local/lib/python3.10/dist-packages/starlette/middleware/errors.py\", line 164, in __call__\n","    await self.app(scope, receive, _send)\n","  File \"/usr/local/lib/python3.10/dist-packages/starlette/middleware/cors.py\", line 85, in __call__\n","    await self.app(scope, receive, send)\n","  File \"/usr/local/lib/python3.10/dist-packages/starlette/middleware/exceptions.py\", line 65, in __call__\n","    await wrap_app_handling_exceptions(self.app, conn)(scope, receive, send)\n","  File \"/usr/local/lib/python3.10/dist-packages/starlette/_exception_handler.py\", line 64, in wrapped_app\n","    raise exc\n","  File \"/usr/local/lib/python3.10/dist-packages/starlette/_exception_handler.py\", line 53, in wrapped_app\n","    await app(scope, receive, sender)\n","  File \"/usr/local/lib/python3.10/dist-packages/starlette/routing.py\", line 756, in __call__\n","    await self.middleware_stack(scope, receive, send)\n","  File \"/usr/local/lib/python3.10/dist-packages/starlette/routing.py\", line 776, in app\n","    await route.handle(scope, receive, send)\n","  File \"/usr/local/lib/python3.10/dist-packages/starlette/routing.py\", line 297, in handle\n","    await self.app(scope, receive, send)\n","  File \"/usr/local/lib/python3.10/dist-packages/starlette/routing.py\", line 77, in app\n","    await wrap_app_handling_exceptions(app, request)(scope, receive, send)\n","  File \"/usr/local/lib/python3.10/dist-packages/starlette/_exception_handler.py\", line 64, in wrapped_app\n","    raise exc\n","  File \"/usr/local/lib/python3.10/dist-packages/starlette/_exception_handler.py\", line 53, in wrapped_app\n","    await app(scope, receive, sender)\n","  File \"/usr/local/lib/python3.10/dist-packages/starlette/routing.py\", line 72, in app\n","    response = await func(request)\n","  File \"/usr/local/lib/python3.10/dist-packages/fastapi/routing.py\", line 278, in app\n","    raw_response = await run_endpoint_function(\n","  File \"/usr/local/lib/python3.10/dist-packages/fastapi/routing.py\", line 191, in run_endpoint_function\n","    return await dependant.call(**values)\n","  File \"/content/drive/MyDrive/MultiOn/main.py\", line 115, in get_visual_prompt\n","    browse = multion.browse(cmd=input_command[0],local=True)\n","  File \"/usr/local/lib/python3.10/dist-packages/multion/client.py\", line 135, in browse\n","    _response = self._client_wrapper.httpx_client.request(\n","  File \"/usr/local/lib/python3.10/dist-packages/multion/core/http_client.py\", line 94, in request\n","    response = self.httpx_client.request(*args, **kwargs)\n","  File \"/usr/local/lib/python3.10/dist-packages/httpx/_client.py\", line 827, in request\n","    return self.send(request, auth=auth, follow_redirects=follow_redirects)\n","  File \"/usr/local/lib/python3.10/dist-packages/httpx/_client.py\", line 914, in send\n","    response = self._send_handling_auth(\n","  File \"/usr/local/lib/python3.10/dist-packages/httpx/_client.py\", line 942, in _send_handling_auth\n","    response = self._send_handling_redirects(\n","  File \"/usr/local/lib/python3.10/dist-packages/httpx/_client.py\", line 979, in _send_handling_redirects\n","    response = self._send_single_request(request)\n","  File \"/usr/local/lib/python3.10/dist-packages/httpx/_client.py\", line 1015, in _send_single_request\n","    response = transport.handle_request(request)\n","  File \"/usr/local/lib/python3.10/dist-packages/httpx/_transports/default.py\", line 232, in handle_request\n","    with map_httpcore_exceptions():\n","  File \"/usr/lib/python3.10/contextlib.py\", line 153, in __exit__\n","    self.gen.throw(typ, value, traceback)\n","  File \"/usr/local/lib/python3.10/dist-packages/httpx/_transports/default.py\", line 86, in map_httpcore_exceptions\n","    raise mapped_exc(message) from exc\n","httpx.ReadTimeout: The read operation timed out\n","\u001b[32mINFO\u001b[0m:     35.231.57.121:0 - \"\u001b[1mPOST /get_visual_prompt HTTP/1.1\u001b[0m\" \u001b[91m500 Internal Server Error\u001b[0m\n","\u001b[31mERROR\u001b[0m:    Exception in ASGI application\n","Traceback (most recent call last):\n","  File \"/usr/local/lib/python3.10/dist-packages/httpx/_transports/default.py\", line 69, in map_httpcore_exceptions\n","    yield\n","  File \"/usr/local/lib/python3.10/dist-packages/httpx/_transports/default.py\", line 233, in handle_request\n","    resp = self._pool.handle_request(req)\n","  File \"/usr/local/lib/python3.10/dist-packages/httpcore/_sync/connection_pool.py\", line 216, in handle_request\n","    raise exc from None\n","  File \"/usr/local/lib/python3.10/dist-packages/httpcore/_sync/connection_pool.py\", line 196, in handle_request\n","    response = connection.handle_request(\n","  File \"/usr/local/lib/python3.10/dist-packages/httpcore/_sync/connection.py\", line 101, in handle_request\n","    return self._connection.handle_request(request)\n","  File \"/usr/local/lib/python3.10/dist-packages/httpcore/_sync/http11.py\", line 143, in handle_request\n","    raise exc\n","  File \"/usr/local/lib/python3.10/dist-packages/httpcore/_sync/http11.py\", line 113, in handle_request\n","    ) = self._receive_response_headers(**kwargs)\n","  File \"/usr/local/lib/python3.10/dist-packages/httpcore/_sync/http11.py\", line 186, in _receive_response_headers\n","    event = self._receive_event(timeout=timeout)\n","  File \"/usr/local/lib/python3.10/dist-packages/httpcore/_sync/http11.py\", line 224, in _receive_event\n","    data = self._network_stream.read(\n","  File \"/usr/local/lib/python3.10/dist-packages/httpcore/_backends/sync.py\", line 124, in read\n","    with map_exceptions(exc_map):\n","  File \"/usr/lib/python3.10/contextlib.py\", line 153, in __exit__\n","    self.gen.throw(typ, value, traceback)\n","  File \"/usr/local/lib/python3.10/dist-packages/httpcore/_exceptions.py\", line 14, in map_exceptions\n","    raise to_exc(exc) from exc\n","httpcore.ReadTimeout: The read operation timed out\n","\n","The above exception was the direct cause of the following exception:\n","\n","Traceback (most recent call last):\n","  File \"/usr/local/lib/python3.10/dist-packages/uvicorn/protocols/http/httptools_impl.py\", line 411, in run_asgi\n","    result = await app(  # type: ignore[func-returns-value]\n","  File \"/usr/local/lib/python3.10/dist-packages/uvicorn/middleware/proxy_headers.py\", line 69, in __call__\n","    return await self.app(scope, receive, send)\n","  File \"/usr/local/lib/python3.10/dist-packages/fastapi/applications.py\", line 1054, in __call__\n","    await super().__call__(scope, receive, send)\n","  File \"/usr/local/lib/python3.10/dist-packages/starlette/applications.py\", line 123, in __call__\n","    await self.middleware_stack(scope, receive, send)\n","  File \"/usr/local/lib/python3.10/dist-packages/starlette/middleware/errors.py\", line 186, in __call__\n","    raise exc\n","  File \"/usr/local/lib/python3.10/dist-packages/starlette/middleware/errors.py\", line 164, in __call__\n","    await self.app(scope, receive, _send)\n","  File \"/usr/local/lib/python3.10/dist-packages/starlette/middleware/cors.py\", line 85, in __call__\n","    await self.app(scope, receive, send)\n","  File \"/usr/local/lib/python3.10/dist-packages/starlette/middleware/exceptions.py\", line 65, in __call__\n","    await wrap_app_handling_exceptions(self.app, conn)(scope, receive, send)\n","  File \"/usr/local/lib/python3.10/dist-packages/starlette/_exception_handler.py\", line 64, in wrapped_app\n","    raise exc\n","  File \"/usr/local/lib/python3.10/dist-packages/starlette/_exception_handler.py\", line 53, in wrapped_app\n","    await app(scope, receive, sender)\n","  File \"/usr/local/lib/python3.10/dist-packages/starlette/routing.py\", line 756, in __call__\n","    await self.middleware_stack(scope, receive, send)\n","  File \"/usr/local/lib/python3.10/dist-packages/starlette/routing.py\", line 776, in app\n","    await route.handle(scope, receive, send)\n","  File \"/usr/local/lib/python3.10/dist-packages/starlette/routing.py\", line 297, in handle\n","    await self.app(scope, receive, send)\n","  File \"/usr/local/lib/python3.10/dist-packages/starlette/routing.py\", line 77, in app\n","    await wrap_app_handling_exceptions(app, request)(scope, receive, send)\n","  File \"/usr/local/lib/python3.10/dist-packages/starlette/_exception_handler.py\", line 64, in wrapped_app\n","    raise exc\n","  File \"/usr/local/lib/python3.10/dist-packages/starlette/_exception_handler.py\", line 53, in wrapped_app\n","    await app(scope, receive, sender)\n","  File \"/usr/local/lib/python3.10/dist-packages/starlette/routing.py\", line 72, in app\n","    response = await func(request)\n","  File \"/usr/local/lib/python3.10/dist-packages/fastapi/routing.py\", line 278, in app\n","    raw_response = await run_endpoint_function(\n","  File \"/usr/local/lib/python3.10/dist-packages/fastapi/routing.py\", line 191, in run_endpoint_function\n","    return await dependant.call(**values)\n","  File \"/content/drive/MyDrive/MultiOn/main.py\", line 115, in get_visual_prompt\n","    browse = multion.browse(cmd=input_command[0],local=True)\n","  File \"/usr/local/lib/python3.10/dist-packages/multion/client.py\", line 135, in browse\n","    _response = self._client_wrapper.httpx_client.request(\n","  File \"/usr/local/lib/python3.10/dist-packages/multion/core/http_client.py\", line 94, in request\n","    response = self.httpx_client.request(*args, **kwargs)\n","  File \"/usr/local/lib/python3.10/dist-packages/httpx/_client.py\", line 827, in request\n","    return self.send(request, auth=auth, follow_redirects=follow_redirects)\n","  File \"/usr/local/lib/python3.10/dist-packages/httpx/_client.py\", line 914, in send\n","    response = self._send_handling_auth(\n","  File \"/usr/local/lib/python3.10/dist-packages/httpx/_client.py\", line 942, in _send_handling_auth\n","    response = self._send_handling_redirects(\n","  File \"/usr/local/lib/python3.10/dist-packages/httpx/_client.py\", line 979, in _send_handling_redirects\n","    response = self._send_single_request(request)\n","  File \"/usr/local/lib/python3.10/dist-packages/httpx/_client.py\", line 1015, in _send_single_request\n","    response = transport.handle_request(request)\n","  File \"/usr/local/lib/python3.10/dist-packages/httpx/_transports/default.py\", line 232, in handle_request\n","    with map_httpcore_exceptions():\n","  File \"/usr/lib/python3.10/contextlib.py\", line 153, in __exit__\n","    self.gen.throw(typ, value, traceback)\n","  File \"/usr/local/lib/python3.10/dist-packages/httpx/_transports/default.py\", line 86, in map_httpcore_exceptions\n","    raise mapped_exc(message) from exc\n","httpx.ReadTimeout: The read operation timed out\n","\u001b[32mINFO\u001b[0m:     35.231.57.121:0 - \"\u001b[1mPOST /get_visual_prompt HTTP/1.1\u001b[0m\" \u001b[91m500 Internal Server Error\u001b[0m\n","\u001b[31mERROR\u001b[0m:    Exception in ASGI application\n","Traceback (most recent call last):\n","  File \"/usr/local/lib/python3.10/dist-packages/httpx/_transports/default.py\", line 69, in map_httpcore_exceptions\n","    yield\n","  File \"/usr/local/lib/python3.10/dist-packages/httpx/_transports/default.py\", line 233, in handle_request\n","    resp = self._pool.handle_request(req)\n","  File \"/usr/local/lib/python3.10/dist-packages/httpcore/_sync/connection_pool.py\", line 216, in handle_request\n","    raise exc from None\n","  File \"/usr/local/lib/python3.10/dist-packages/httpcore/_sync/connection_pool.py\", line 196, in handle_request\n","    response = connection.handle_request(\n","  File \"/usr/local/lib/python3.10/dist-packages/httpcore/_sync/connection.py\", line 101, in handle_request\n","    return self._connection.handle_request(request)\n","  File \"/usr/local/lib/python3.10/dist-packages/httpcore/_sync/http11.py\", line 143, in handle_request\n","    raise exc\n","  File \"/usr/local/lib/python3.10/dist-packages/httpcore/_sync/http11.py\", line 113, in handle_request\n","    ) = self._receive_response_headers(**kwargs)\n","  File \"/usr/local/lib/python3.10/dist-packages/httpcore/_sync/http11.py\", line 186, in _receive_response_headers\n","    event = self._receive_event(timeout=timeout)\n","  File \"/usr/local/lib/python3.10/dist-packages/httpcore/_sync/http11.py\", line 224, in _receive_event\n","    data = self._network_stream.read(\n","  File \"/usr/local/lib/python3.10/dist-packages/httpcore/_backends/sync.py\", line 124, in read\n","    with map_exceptions(exc_map):\n","  File \"/usr/lib/python3.10/contextlib.py\", line 153, in __exit__\n","    self.gen.throw(typ, value, traceback)\n","  File \"/usr/local/lib/python3.10/dist-packages/httpcore/_exceptions.py\", line 14, in map_exceptions\n","    raise to_exc(exc) from exc\n","httpcore.ReadTimeout: The read operation timed out\n","\n","The above exception was the direct cause of the following exception:\n","\n","Traceback (most recent call last):\n","  File \"/usr/local/lib/python3.10/dist-packages/uvicorn/protocols/http/httptools_impl.py\", line 411, in run_asgi\n","    result = await app(  # type: ignore[func-returns-value]\n","  File \"/usr/local/lib/python3.10/dist-packages/uvicorn/middleware/proxy_headers.py\", line 69, in __call__\n","    return await self.app(scope, receive, send)\n","  File \"/usr/local/lib/python3.10/dist-packages/fastapi/applications.py\", line 1054, in __call__\n","    await super().__call__(scope, receive, send)\n","  File \"/usr/local/lib/python3.10/dist-packages/starlette/applications.py\", line 123, in __call__\n","    await self.middleware_stack(scope, receive, send)\n","  File \"/usr/local/lib/python3.10/dist-packages/starlette/middleware/errors.py\", line 186, in __call__\n","    raise exc\n","  File \"/usr/local/lib/python3.10/dist-packages/starlette/middleware/errors.py\", line 164, in __call__\n","    await self.app(scope, receive, _send)\n","  File \"/usr/local/lib/python3.10/dist-packages/starlette/middleware/cors.py\", line 85, in __call__\n","    await self.app(scope, receive, send)\n","  File \"/usr/local/lib/python3.10/dist-packages/starlette/middleware/exceptions.py\", line 65, in __call__\n","    await wrap_app_handling_exceptions(self.app, conn)(scope, receive, send)\n","  File \"/usr/local/lib/python3.10/dist-packages/starlette/_exception_handler.py\", line 64, in wrapped_app\n","    raise exc\n","  File \"/usr/local/lib/python3.10/dist-packages/starlette/_exception_handler.py\", line 53, in wrapped_app\n","    await app(scope, receive, sender)\n","  File \"/usr/local/lib/python3.10/dist-packages/starlette/routing.py\", line 756, in __call__\n","    await self.middleware_stack(scope, receive, send)\n","  File \"/usr/local/lib/python3.10/dist-packages/starlette/routing.py\", line 776, in app\n","    await route.handle(scope, receive, send)\n","  File \"/usr/local/lib/python3.10/dist-packages/starlette/routing.py\", line 297, in handle\n","    await self.app(scope, receive, send)\n","  File \"/usr/local/lib/python3.10/dist-packages/starlette/routing.py\", line 77, in app\n","    await wrap_app_handling_exceptions(app, request)(scope, receive, send)\n","  File \"/usr/local/lib/python3.10/dist-packages/starlette/_exception_handler.py\", line 64, in wrapped_app\n","    raise exc\n","  File \"/usr/local/lib/python3.10/dist-packages/starlette/_exception_handler.py\", line 53, in wrapped_app\n","    await app(scope, receive, sender)\n","  File \"/usr/local/lib/python3.10/dist-packages/starlette/routing.py\", line 72, in app\n","    response = await func(request)\n","  File \"/usr/local/lib/python3.10/dist-packages/fastapi/routing.py\", line 278, in app\n","    raw_response = await run_endpoint_function(\n","  File \"/usr/local/lib/python3.10/dist-packages/fastapi/routing.py\", line 191, in run_endpoint_function\n","    return await dependant.call(**values)\n","  File \"/content/drive/MyDrive/MultiOn/main.py\", line 115, in get_visual_prompt\n","    browse = multion.browse(cmd=input_command[0],local=True)\n","  File \"/usr/local/lib/python3.10/dist-packages/multion/client.py\", line 135, in browse\n","    _response = self._client_wrapper.httpx_client.request(\n","  File \"/usr/local/lib/python3.10/dist-packages/multion/core/http_client.py\", line 94, in request\n","    response = self.httpx_client.request(*args, **kwargs)\n","  File \"/usr/local/lib/python3.10/dist-packages/httpx/_client.py\", line 827, in request\n","    return self.send(request, auth=auth, follow_redirects=follow_redirects)\n","  File \"/usr/local/lib/python3.10/dist-packages/httpx/_client.py\", line 914, in send\n","    response = self._send_handling_auth(\n","  File \"/usr/local/lib/python3.10/dist-packages/httpx/_client.py\", line 942, in _send_handling_auth\n","    response = self._send_handling_redirects(\n","  File \"/usr/local/lib/python3.10/dist-packages/httpx/_client.py\", line 979, in _send_handling_redirects\n","    response = self._send_single_request(request)\n","  File \"/usr/local/lib/python3.10/dist-packages/httpx/_client.py\", line 1015, in _send_single_request\n","    response = transport.handle_request(request)\n","  File \"/usr/local/lib/python3.10/dist-packages/httpx/_transports/default.py\", line 232, in handle_request\n","    with map_httpcore_exceptions():\n","  File \"/usr/lib/python3.10/contextlib.py\", line 153, in __exit__\n","    self.gen.throw(typ, value, traceback)\n","  File \"/usr/local/lib/python3.10/dist-packages/httpx/_transports/default.py\", line 86, in map_httpcore_exceptions\n","    raise mapped_exc(message) from exc\n","httpx.ReadTimeout: The read operation timed out\n","\u001b[32mINFO\u001b[0m:     Shutting down\n","\u001b[32mINFO\u001b[0m:     Waiting for application shutdown.\n","\u001b[32mINFO\u001b[0m:     Application shutdown complete.\n","\u001b[32mINFO\u001b[0m:     Finished server process [\u001b[36m70533\u001b[0m]\n","Traceback (most recent call last):\n","  File \"/content/drive/MyDrive/MultiOn/main.py\", line 124, in <module>\n","    uvicorn.run(app,port=8000)\n","  File \"/usr/local/lib/python3.10/dist-packages/uvicorn/main.py\", line 575, in run\n","    server.run()\n","  File \"/usr/local/lib/python3.10/dist-packages/uvicorn/server.py\", line 65, in run\n","    return asyncio.run(self.serve(sockets=sockets))\n","  File \"/usr/local/lib/python3.10/dist-packages/nest_asyncio.py\", line 30, in run\n","    return loop.run_until_complete(task)\n","  File \"uvloop/loop.pyx\", line 1511, in uvloop.loop.Loop.run_until_complete\n","  File \"uvloop/loop.pyx\", line 1504, in uvloop.loop.Loop.run_until_complete\n","  File \"uvloop/loop.pyx\", line 1377, in uvloop.loop.Loop.run_forever\n","  File \"uvloop/loop.pyx\", line 555, in uvloop.loop.Loop._run\n","  File \"uvloop/loop.pyx\", line 474, in uvloop.loop.Loop._on_idle\n","  File \"uvloop/cbhandles.pyx\", line 83, in uvloop.loop.Handle._run\n","  File \"uvloop/cbhandles.pyx\", line 63, in uvloop.loop.Handle._run\n","  File \"/usr/lib/python3.10/asyncio/tasks.py\", line 315, in __wakeup\n","    self.__step()\n","  File \"/usr/lib/python3.10/asyncio/tasks.py\", line 232, in __step\n","    result = coro.send(None)\n","  File \"/usr/local/lib/python3.10/dist-packages/uvicorn/server.py\", line 68, in serve\n","    with self.capture_signals():\n","  File \"/usr/lib/python3.10/contextlib.py\", line 142, in __exit__\n","    next(self.gen)\n","  File \"/usr/local/lib/python3.10/dist-packages/uvicorn/server.py\", line 328, in capture_signals\n","    signal.raise_signal(captured_signal)\n","KeyboardInterrupt\n","^C\n"]}]},{"cell_type":"code","source":[],"metadata":{"id":"Xdq1MOYWwWMA"},"execution_count":null,"outputs":[]}]}